Workbook
Name Segment_Category: #N/A
Name Segment_Channel_clean: #N/A
Name Segment_Region: #N/A

Sheet Project_Brief
A1: Excel Portfolio Project #1 — Northstar Retail Sales Analysis
A4: Business Scenario
A5: You are a junior data analyst at Northstar Retail Canada. Management wants a 2025 performance review showing sales, profit, customers, products, channels, returns and performance versus monthly targets. The raw export is intentionally messy. Your job is to clean it, validate it, analyze it and build an executive Excel dashboard.
A9: Your Build — Do NOT skip steps
A10: Stage | B10: What you should build | C10: Core Excel concepts
A11: 1. Audit | B11: Check row count, blanks, duplicate Order_IDs, inconsistent categories, key quality. | C11: COUNTIF/COUNTIFS, filters, conditional formatting
A12: 2. Clean | B12: Create a new Cleaned_Data sheet. Normalize spaces/text and standardize categories. | C12: TRIM, CLEAN, SUBSTITUTE, UPPER/LOWER/PROPER, IF
A13: 3. Parse | B13: Extract Customer Name, City and Segment from Customer_Info. | C13: FIND, MID, LEFT, RIGHT, LEN — including finding the 2nd comma
A14: 4. Enrich | B14: Bring Product, Category, Unit Cost, Region and customer segment into Cleaned_Data. | C14: XLOOKUP; then redo one lookup with INDEX+MATCH
A15: 5. Calculate | B15: Create Gross Sales, Discount Amount, Net Sales, Total Cost, Profit, Profit Margin. | C15: Arithmetic, IF/IFERROR, absolute/relative references
A16: 6. Date fields | B16: Create Month, Month Number, Quarter and Year. | C16: YEAR, MONTH, TEXT, date logic
A17: 7. Analyze | B17: Answer the business questions below using PivotTables and/or SUMIFS/COUNTIFS. | C17: PivotTables, SUMIFS, COUNTIFS, aggregation
A18: 8. Dashboard | B18: Build one-page dashboard with KPIs + charts + filters/slicers. | C18: PivotCharts, charts, KPI design, formatting
A19: 9. QA | B19: Reconcile dashboard totals to cleaned transactions and document assumptions. | C19: Data validation, error checks, reconciliation
A20: 10. GitHub | B20: Publish workbook + README + screenshots + key findings. | C20: Portfolio storytelling
A22: Business Questions Your Analysis Must Answer
A23: 1 | B23: What were total Net Sales, Profit, Profit Margin and unique Orders in 2025?
A24: 2 | B24: Which months beat or missed sales and profit targets?
A25: 3 | B25: Which product categories and products generated the most sales and profit?
A26: 4 | B26: Which regions and customer segments are most valuable?
A27: 5 | B27: How do Online, Retail Store and Marketplace channels compare?
A28: 6 | B28: Which products have high sales but weak profit margin?
A29: 7 | B29: Do larger discounts appear to improve revenue at the expense of margin?
A30: 8 | B30: Which channels/regions have the highest return rate?
A31: 9 | B31: What are the top 10 customers by Net Sales?
A32: 10 | B32: What 3 actions would you recommend to management based on your analysis?
A34: Final GitHub Deliverables
A35: File | B35: Purpose
A36: Northstar_Retail_Analysis.xlsx | B36: Your completed cleaned data, analysis and dashboard.
A37: README.md | B37: Business problem, cleaning steps, analysis, findings and recommendations.
A38: dashboard.png | B38: Screenshot of your final dashboard for the repo landing page.
A39: Optional: cleaned_sales.csv | B39: Cleaned dataset for future SQL/Python reuse.

Sheet Raw_Sales
A1: Order_ID | B1: Order_Date | C1: Customer_ID | D1: Product_ID | E1: Customer_Info | F1: Store_Raw | G1: Salesperson | H1: Channel_Raw | I1: Quantity | J1: Unit_Price | K1: Discount_Pct | L1: Payment_Method_Raw | M1: Delivery_Days | N1: Return_Status | O1: Channel_clean | P1: Store_clean | Q1: Payment_Method_clean | R1: Customer_ID_clean | S1: Customer_Name | T1: Customer_City | U1: Customer_Segment | V1: Product_Name | W1: Category | X1: Unit_Cost | Y1: Gross_Sales | Z1: Discount_Amount | AA1: Net_Sales | AB1: Total_Cost | AC1: Profit | AD1: Profit_Margin | AE1: Return_Flag | AF1: Year | AG1: Month_Number | AH1: Month | AI1: Quarter | AJ1: Month_Start | AK1: Region
A2: ORD-2025-00123 | B2: 45661 | C2: C0064 | D2: P1002 | E2: Amine Khan , Edmonton , Consumer | F2: Vancouver West | G2: M. Wilson | H2: Retail Store | I2: 1 | J2: 38.4 | K2: 0.15 | L2: Credit Card | M2: 4 | N2: No | O2: =SUBSTITUTE(PROPER(TRIM(RawSalesTable[[#This Row],[Channel_Raw]])), "Market Place", "Marketplace") -> Retail Store | P2: =TRIM(RawSalesTable[[#This Row],[Store_Raw]]) -> Vancouver West | Q2: =IF(TRIM(RawSalesTable[[#This Row],[Payment_Method_Raw]])="","Non renseigné",SUBSTITUTE(TRIM(RawSalesTable[[#This Row],[Payment_Method_Raw]]),"CC","Credit Card")) -> Credit Card | R2: =UPPER(PROPER(RawSalesTable[[#This Row],[Customer_ID]])) -> C0064 | S2: =TRIM(LEFT(RawSalesTable[[#This Row],[Customer_Info]],FIND(",",RawSalesTable[[#This Row],[Customer_Info]]) -1)) -> Amine Khan | T2: =TRIM(MID(RawSalesTable[[#This Row],[Customer_Info]],FIND(",",RawSalesTable[[#This Row],[Customer_Info]])+1,FIND(",",RawSalesTable[[#This Row],[Customer_Info]],FIND(",",RawSalesTable[[#This Row],[Customer_Info]])+1)-FIND(",",RawSalesTable[[#This Row],[Customer_Info]])-1)) -> Edmonton | U2: =TRIM(RIGHT(RawSalesTable[[#This Row],[Customer_Info]], LEN(RawSalesTable[[#This Row],[Customer_Info]])-FIND(",",RawSalesTable[[#This Row],[Customer_Info]],FIND(",",RawSalesTable[[#This Row],[Customer_Info]])+1))) -> Consumer | V2: =VLOOKUP(RawSalesTable[[#This Row],[Product_ID]],ProductsTable[],2,FALSE) -> Keyboard | W2: =VLOOKUP(RawSalesTable[[#This Row],[Product_ID]],ProductsTable[],3,FALSE) -> Electronics | X2: =VLOOKUP(RawSalesTable[[#This Row],[Product_ID]],ProductsTable[],5,FALSE) -> 23.5 | Y2: =RawSalesTable[[#This Row],[Quantity]]*RawSalesTable[[#This Row],[Unit_Price]] -> 38.4 | Z2: =RawSalesTable[[#This Row],[Gross_Sales]]*RawSalesTable[[#This Row],[Discount_Pct]] -> 5.76 | AA2: =RawSalesTable[[#This Row],[Gross_Sales]]-RawSalesTable[[#This Row],[Discount_Amount]] -> 32.64 | AB2: =RawSalesTable[[#This Row],[Unit_Cost]]*RawSalesTable[[#This Row],[Quantity]] -> 23.5 | AC2: =RawSalesTable[[#This Row],[Net_Sales]]-RawSalesTable[[#This Row],[Total_Cost]] -> 9.14 | AD2: =RawSalesTable[[#This Row],[Profit]]/RawSalesTable[[#This Row],[Net_Sales]] -> 0.28002451 | AE2: =IF(RawSalesTable[[#This Row],[Return_Status]]="Yes",1,0) -> 0 | AF2: =YEAR(RawSalesTable[[#This Row],[Order_Date]]) -> 2025 | AG2: =MONTH(RawSalesTable[[#This Row],[Order_Date]]) -> 1 | AH2: =TEXT(RawSalesTable[[#This Row],[Order_Date]],"mmmm") -> janvier | AI2: =IF(RawSalesTable[[#This Row],[Month_Number]]<=3,"Q1",IF(RawSalesTable[[#This Row],[Month_Number]]<=6,"Q2",IF(RawSalesTable[[#This Row],[Month_Number]]<=9,"Q3","Q4"))) -> Q1 | AJ2: =DATE(YEAR(RawSalesTable[[#This Row],[Order_Date]]),MONTH(RawSalesTable[[#This Row],[Order_Date]]),1) -> 45658 | AK2: =VLOOKUP(RawSalesTable[[#This Row],[Customer_ID_clean]],CustomersTable[],4,FALSE) -> Alberta
A3: ORD-2025-00167 | B3: 45913 | C3: C0106 | D3: P1009 | E3: Liam Gagnon, Ottawa, Small Business | F3: Vancouver West | G3: M. Wilson | H3: Retail Store | I3: 3 | J3: 305.98 | K3: 0.15 | L3: Credit Card | M3: 0 | N3: No | O3: =SUBSTITUTE(PROPER(TRIM(RawSalesTable[[#This Row],[Channel_Raw]])), "Market Place", "Marketplace") -> Retail Store | P3: =TRIM(RawSalesTable[[#This Row],[Store_Raw]]) -> Vancouver West | Q3: =IF(TRIM(RawSalesTable[[#This Row],[Payment_Method_Raw]])="","Non renseigné",SUBSTITUTE(TRIM(RawSalesTable[[#This Row],[Payment_Method_Raw]]),"CC","Credit Card")) -> Credit Card | R3: =UPPER(PROPER(RawSalesTable[[#This Row],[Customer_ID]])) -> C0106 | S3: =TRIM(LEFT(RawSalesTable[[#This Row],[Customer_Info]],FIND(",",RawSalesTable[[#This Row],[Customer_Info]]) -1)) -> Liam Gagnon | T3: =TRIM(MID(RawSalesTable[[#This Row],[Customer_Info]],FIND(",",RawSalesTable[[#This Row],[Customer_Info]])+1,FIND(",",RawSalesTable[[#This Row],[Customer_Info]],FIND(",",RawSalesTable[[#This Row],[Customer_Info]])+1)-FIND(",",RawSalesTable[[#This Row],[Customer_Info]])-1)) -> Ottawa | U3: =TRIM(RIGHT(RawSalesTable[[#This Row],[Customer_Info]], LEN(RawSalesTable[[#This Row],[Customer_Info]])-FIND(",",RawSalesTable[[#This Row],[Customer_Info]],FIND(",",RawSalesTable[[#This Row],[Customer_Info]])+1))) -> Small Business | V3: =VLOOKUP(RawSalesTable[[#This Row],[Product_ID]],ProductsTable[],2,FALSE) -> Notebook | W3: =VLOOKUP(RawSalesTable[[#This Row],[Product_ID]],ProductsTable[],3,FALSE) -> Office | X3: =VLOOKUP(RawSalesTable[[#This Row],[Product_ID]],ProductsTable[],5,FALSE) -> 176.13 | Y3: =RawSalesTable[[#This Row],[Quantity]]*RawSalesTable[[#This Row],[Unit_Price]] -> 917.94 | Z3: =RawSalesTable[[#This Row],[Gross_Sales]]*RawSalesTable[[#This Row],[Discount_Pct]] -> 137.691 | AA3: =RawSalesTable[[#This Row],[Gross_Sales]]-RawSalesTable[[#This Row],[Discount_Amount]] -> 780.249 | AB3: =RawSalesTable[[#This Row],[Unit_Cost]]*RawSalesTable[[#This Row],[Quantity]] -> 528.39 | AC3: =RawSalesTable[[#This Row],[Net_Sales]]-RawSalesTable[[#This Row],[Total_Cost]] -> 251.859 | AD3: =RawSalesTable[[#This Row],[Profit]]/RawSalesTable[[#This Row],[Net_Sales]] -> 0.32279311 | AE3: =IF(RawSalesTable[[#This Row],[Return_Status]]="Yes",1,0) -> 0 | AF3: =YEAR(RawSalesTable[[#This Row],[Order_Date]]) -> 2025 | AG3: =MONTH(RawSalesTable[[#This Row],[Order_Date]]) -> 9 | AH3: =TEXT(RawSalesTable[[#This Row],[Order_Date]],"mmmm") -> septembre | AI3: =IF(RawSalesTable[[#This Row],[Month_Number]]<=3,"Q1",IF(RawSalesTable[[#This Row],[Month_Number]]<=6,"Q2",IF(RawSalesTable[[#This Row],[Month_Number]]<=9,"Q3","Q4"))) -> Q3 | AJ3: =DATE(YEAR(RawSalesTable[[#This Row],[Order_Date]]),MONTH(RawSalesTable[[#This Row],[Order_Date]]),1) -> 45901 | AK3: =VLOOKUP(RawSalesTable[[#This Row],[Customer_ID_clean]],CustomersTable[],4,FALSE) -> Ontario
A4: ORD-2025-00244 | B4: 45923 | C4: C0068 | D4: P1031 | E4: Yasmine Martin, Calgary, Consumer | F4: Calgary North | G4: L. Chen | H4: Marketplace | I4: 3 | J4: 251.49 | K4: 0.15 | L4: Debit Card | M4: 6 | N4: No | O4: =SUBSTITUTE(PROPER(TRIM(RawSalesTable[[#This Row],[Channel_Raw]])), "Market Place", "Marketplace") -> Marketplace | P4: =TRIM(RawSalesTable[[#This Row],[Store_Raw]]) -> Calgary North | Q4: =IF(TRIM(RawSalesTable[[#This Row],[Payment_Method_Raw]])="","Non renseigné",SUBSTITUTE(TRIM(RawSalesTable[[#This Row],[Payment_Method_Raw]]),"CC","Credit Card")) -> Debit Card | R4: =UPPER(PROPER(RawSalesTable[[#This Row],[Customer_ID]])) -> C0068 | S4: =TRIM(LEFT(RawSalesTable[[#This Row],[Customer_Info]],FIND(",",RawSalesTable[[#This Row],[Customer_Info]]) -1)) -> Yasmine Martin | T4: =TRIM(MID(RawSalesTable[[#This Row],[Customer_Info]],FIND(",",RawSalesTable[[#This Row],[Customer_Info]])+1,FIND(",",RawSalesTable[[#This Row],[Customer_Info]],FIND(",",RawSalesTable[[#This Row],[Customer_Info]])+1)-FIND(",",RawSalesTable[[#This Row],[Customer_Info]])-1)) -> Calgary | U4: =TRIM(RIGHT(RawSalesTable[[#This Row],[Customer_Info]], LEN(RawSalesTable[[#This Row],[Customer_Info]])-FIND(",",RawSalesTable[[#This Row],[Customer_Info]],FIND(",",RawSalesTable[[#This Row],[Customer_Info]])+1))) -> Consumer | V4: =VLOOKUP(RawSalesTable[[#This Row],[Product_ID]],ProductsTable[],2,FALSE) -> Dumbbell Set | W4: =VLOOKUP(RawSalesTable[[#This Row],[Product_ID]],ProductsTable[],3,FALSE) -> Fitness | X4: =VLOOKUP(RawSalesTable[[#This Row],[Product_ID]],ProductsTable[],5,FALSE) -> 131.73 | Y4: =RawSalesTable[[#This Row],[Quantity]]*RawSalesTable[[#This Row],[Unit_Price]] -> 754.47 | Z4: =RawSalesTable[[#This Row],[Gross_Sales]]*RawSalesTable[[#This Row],[Discount_Pct]] -> 113.1705 | AA4: =RawSalesTable[[#This Row],[Gross_Sales]]-RawSalesTable[[#This Row],[Discount_Amount]] -> 641.2995 | AB4: =RawSalesTable[[#This Row],[Unit_Cost]]*RawSalesTable[[#This Row],[Quantity]] -> 395.19 | AC4: =RawSalesTable[[#This Row],[Net_Sales]]-RawSalesTable[[#This Row],[Total_Cost]] -> 246.1095 | AD4: =RawSalesTable[[#This Row],[Profit]]/RawSalesTable[[#This Row],[Net_Sales]] -> 0.38376687 | AE4: =IF(RawSalesTable[[#This Row],[Return_Status]]="Yes",1,0) -> 0 | AF4: =YEAR(RawSalesTable[[#This Row],[Order_Date]]) -> 2025 | AG4: =MONTH(RawSalesTable[[#This Row],[Order_Date]]) -> 9 | AH4: =TEXT(RawSalesTable[[#This Row],[Order_Date]],"mmmm") -> septembre | AI4: =IF(RawSalesTable[[#This Row],[Month_Number]]<=3,"Q1",IF(RawSalesTable[[#This Row],[Month_Number]]<=6,"Q2",IF(RawSalesTable[[#This Row],[Month_Number]]<=9,"Q3","Q4"))) -> Q3 | AJ4: =DATE(YEAR(RawSalesTable[[#This Row],[Order_Date]]),MONTH(RawSalesTable[[#This Row],[Order_Date]]),1) -> 45901 | AK4: =VLOOKUP(RawSalesTable[[#This Row],[Customer_ID_clean]],CustomersTable[],4,FALSE) -> Alberta
A5: ORD-2025-00278 | B5: 45758 | C5: C0041 | D5: P1022 | E5: Amine Chen , Halifax , Small Business | F5: Montreal Central | G5: J. Tremblay | H5: Retail Store | I5: 2 | J5: 405.16 | K5: 0 | L5: Credit Card | M5: 1 | N5: No | O5: =SUBSTITUTE(PROPER(TRIM(RawSalesTable[[#This Row],[Channel_Raw]])), "Market Place", "Marketplace") -> Retail Store | P5: =TRIM(RawSalesTable[[#This Row],[Store_Raw]]) -> Montreal Central | Q5: =IF(TRIM(RawSalesTable[[#This Row],[Payment_Method_Raw]])="","Non renseigné",SUBSTITUTE(TRIM(RawSalesTable[[#This Row],[Payment_Method_Raw]]),"CC","Credit Card")) -> Credit Card | R5: =UPPER(PROPER(RawSalesTable[[#This Row],[Customer_ID]])) -> C0041 | S5: =TRIM(LEFT(RawSalesTable[[#This Row],[Customer_Info]],FIND(",",RawSalesTable[[#This Row],[Customer_Info]]) -1)) -> Amine Chen | T5: =TRIM(MID(RawSalesTable[[#This Row],[Customer_Info]],FIND(",",RawSalesTable[[#This Row],[Customer_Info]])+1,FIND(",",RawSalesTable[[#This Row],[Customer_Info]],FIND(",",RawSalesTable[[#This Row],[Customer_Info]])+1)-FIND(",",RawSalesTable[[#This Row],[Customer_Info]])-1)) -> Halifax | U5: =TRIM(RIGHT(RawSalesTable[[#This Row],[Customer_Info]], LEN(RawSalesTable[[#This Row],[Customer_Info]])-FIND(",",RawSalesTable[[#This Row],[Customer_Info]],FIND(",",RawSalesTable[[#This Row],[Customer_Info]])+1))) -> Small Business | V5: =VLOOKUP(RawSalesTable[[#This Row],[Product_ID]],ProductsTable[],2,FALSE) -> Humidifier | W5: =VLOOKUP(RawSalesTable[[#This Row],[Product_ID]],ProductsTable[],3,FALSE) -> Home | X5: =VLOOKUP(RawSalesTable[[#This Row],[Product_ID]],ProductsTable[],5,FALSE) -> 239.67 | Y5: =RawSalesTable[[#This Row],[Quantity]]*RawSalesTable[[#This Row],[Unit_Price]] -> 810.32 | Z5: =RawSalesTable[[#This Row],[Gross_Sales]]*RawSalesTable[[#This Row],[Discount_Pct]] -> 0 | AA5: =RawSalesTable[[#This Row],[Gross_Sales]]-RawSalesTable[[#This Row],[Discount_Amount]] -> 810.32 | AB5: =RawSalesTable[[#This Row],[Unit_Cost]]*RawSalesTable[[#This Row],[Quantity]] -> 479.34 | AC5: =RawSalesTable[[#This Row],[Net_Sales]]-RawSalesTable[[#This Row],[Total_Cost]] -> 330.98 | AD5: =RawSalesTable[[#This Row],[Profit]]/RawSalesTable[[#This Row],[Net_Sales]] -> 0.40845592 | AE5: =IF(RawSalesTable[[#This Row],[Return_Status]]="Yes",1,0) -> 0 | AF5: =YEAR(RawSalesTable[[#This Row],[Order_Date]]) -> 2025 | AG5: =MONTH(RawSalesTable[[#This Row],[Order_Date]]) -> 4 | AH5: =TEXT(RawSalesTable[[#This Row],[Order_Date]],"mmmm") -> avril | AI5: =IF(RawSalesTable[[#This Row],[Month_Number]]<=3,"Q1",IF(RawSalesTable[[#This Row],[Month_Number]]<=6,"Q2",IF(RawSalesTable[[#This Row],[Month_Number]]<=9,"Q3","Q4"))) -> Q2 | AJ5: =DATE(YEAR(RawSalesTable[[#This Row],[Order_Date]]),MONTH(RawSalesTable[[#This Row],[Order_Date]]),1) -> 45748 | AK5: =VLOOKUP(RawSalesTable[[#This Row],[Customer_ID_clean]],CustomersTable[],4,FALSE) -> Nova Scotia
A6: ORD-2025-00308 | B6: 45995 | C6: C0091 | D6: P1039 | E6: Leo Taylor, Victoria, Small Business | F6: Montreal Central | G6: A. Morgan | H6: Online | I6: 1 | J6: 341.39 | K6: 0 | M6: 4 | N6: No | O6: =SUBSTITUTE(PROPER(TRIM(RawSalesTable[[#This Row],[Channel_Raw]])), "Market Place", "Marketplace") -> Online | P6: =TRIM(RawSalesTable[[#This Row],[Store_Raw]]) -> Montreal Central | Q6: =IF(TRIM(RawSalesTable[[#This Row],[Payment_Method_Raw]])="","Non renseigné",SUBSTITUTE(TRIM(RawSalesTable[[#This Row],[Payment_Method_Raw]]),"CC","Credit Card")) -> Non renseigné | R6: =UPPER(PROPER(RawSalesTable[[#This Row],[Customer_ID]])) -> C0091 | S6: =TRIM(LEFT(RawSalesTable[[#This Row],[Customer_Info]],FIND(",",RawSalesTable[[#This Row],[Customer_Info]]) -1)) -> Leo Taylor | T6: =TRIM(MID(RawSalesTable[[#This Row],[Customer_Info]],FIND(",",RawSalesTable[[#This Row],[Customer_Info]])+1,FIND(",",RawSalesTable[[#This Row],[Customer_Info]],FIND(",",RawSalesTable[[#This Row],[Customer_Info]])+1)-FIND(",",RawSalesTable[[#This Row],[Customer_Info]])-1)) -> Victoria | U6: =TRIM(RIGHT(RawSalesTable[[#This Row],[Customer_Info]], LEN(RawSalesTable[[#This Row],[Customer_Info]])-FIND(",",RawSalesTable[[#This Row],[Customer_Info]],FIND(",",RawSalesTable[[#This Row],[Customer_Info]])+1))) -> Small Business | V6: =VLOOKUP(RawSalesTable[[#This Row],[Product_ID]],ProductsTable[],2,FALSE) -> Travel Adapter | W6: =VLOOKUP(RawSalesTable[[#This Row],[Product_ID]],ProductsTable[],3,FALSE) -> Accessories | X6: =VLOOKUP(RawSalesTable[[#This Row],[Product_ID]],ProductsTable[],5,FALSE) -> 229.86 | Y6: =RawSalesTable[[#This Row],[Quantity]]*RawSalesTable[[#This Row],[Unit_Price]] -> 341.39 | Z6: =RawSalesTable[[#This Row],[Gross_Sales]]*RawSalesTable[[#This Row],[Discount_Pct]] -> 0 | AA6: =RawSalesTable[[#This Row],[Gross_Sales]]-RawSalesTable[[#This Row],[Discount_Amount]] -> 341.39 | AB6: =RawSalesTable[[#This Row],[Unit_Cost]]*RawSalesTable[[#This Row],[Quantity]] -> 229.86 | AC6: =RawSalesTable[[#This Row],[Net_Sales]]-RawSalesTable[[#This Row],[Total_Cost]] -> 111.53 | AD6: =RawSalesTable[[#This Row],[Profit]]/RawSalesTable[[#This Row],[Net_Sales]] -> 0.32669381 | AE6: =IF(RawSalesTable[[#This Row],[Return_Status]]="Yes",1,0) -> 0 | AF6: =YEAR(RawSalesTable[[#This Row],[Order_Date]]) -> 2025 | AG6: =MONTH(RawSalesTable[[#This Row],[Order_Date]]) -> 12 | AH6: =TEXT(RawSalesTable[[#This Row],[Order_Date]],"mmmm") -> décembre | AI6: =IF(RawSalesTable[[#This Row],[Month_Number]]<=3,"Q1",IF(RawSalesTable[[#This Row],[Month_Number]]<=6,"Q2",IF(RawSalesTable[[#This Row],[Month_Number]]<=9,"Q3","Q4"))) -> Q4 | AJ6: =DATE(YEAR(RawSalesTable[[#This Row],[Order_Date]]),MONTH(RawSalesTable[[#This Row],[Order_Date]]),1) -> 45992 | AK6: =VLOOKUP(RawSalesTable[[#This Row],[Customer_ID_clean]],CustomersTable[],4,FALSE) -> British Columbia
A7: ORD-2025-00464 | B7: 45781 | C7: C0047 | D7: P1038 | E7: Amine King, Victoria, Consumer | F7: Montreal Central | G7: E. Roy | H7: Retail Store | I7: 1 | J7: 273.39 | K7: 0.1 | L7: PayPal | M7: 3 | N7: No | O7: =SUBSTITUTE(PROPER(TRIM(RawSalesTable[[#This Row],[Channel_Raw]])), "Market Place", "Marketplace") -> Retail Store | P7: =TRIM(RawSalesTable[[#This Row],[Store_Raw]]) -> Montreal Central | Q7: =IF(TRIM(RawSalesTable[[#This Row],[Payment_Method_Raw]])="","Non renseigné",SUBSTITUTE(TRIM(RawSalesTable[[#This Row],[Payment_Method_Raw]]),"CC","Credit Card")) -> PayPal | R7: =UPPER(PROPER(RawSalesTable[[#This Row],[Customer_ID]])) -> C0047 | S7: =TRIM(LEFT(RawSalesTable[[#This Row],[Customer_Info]],FIND(",",RawSalesTable[[#This Row],[Customer_Info]]) -1)) -> Amine King | T7: =TRIM(MID(RawSalesTable[[#This Row],[Customer_Info]],FIND(",",RawSalesTable[[#This Row],[Customer_Info]])+1,FIND(",",RawSalesTable[[#This Row],[Customer_Info]],FIND(",",RawSalesTable[[#This Row],[Customer_Info]])+1)-FIND(",",RawSalesTable[[#This Row],[Customer_Info]])-1)) -> Victoria | U7: =TRIM(RIGHT(RawSalesTable[[#This Row],[Customer_Info]], LEN(RawSalesTable[[#This Row],[Customer_Info]])-FIND(",",RawSalesTable[[#This Row],[Customer_Info]],FIND(",",RawSalesTable[[#This Row],[Customer_Info]])+1))) -> Consumer | V7: =VLOOKUP(RawSalesTable[[#This Row],[Product_ID]],ProductsTable[],2,FALSE) -> Water Bottle | W7: =VLOOKUP(RawSalesTable[[#This Row],[Product_ID]],ProductsTable[],3,FALSE) -> Accessories | X7: =VLOOKUP(RawSalesTable[[#This Row],[Product_ID]],ProductsTable[],5,FALSE) -> 119.16 | Y7: =RawSalesTable[[#This Row],[Quantity]]*RawSalesTable[[#This Row],[Unit_Price]] -> 273.39 | Z7: =RawSalesTable[[#This Row],[Gross_Sales]]*RawSalesTable[[#This Row],[Discount_Pct]] -> 27.339 | AA7: =RawSalesTable[[#This Row],[Gross_Sales]]-RawSalesTable[[#This Row],[Discount_Amount]] -> 246.051 | AB7: =RawSalesTable[[#This Row],[Unit_Cost]]*RawSalesTable[[#This Row],[Quantity]] -> 119.16 | AC7: =RawSalesTable[[#This Row],[Net_Sales]]-RawSalesTable[[#This Row],[Total_Cost]] -> 126.891 | AD7: =RawSalesTable[[#This Row],[Profit]]/RawSalesTable[[#This Row],[Net_Sales]] -> 0.51571016 | AE7: =IF(RawSalesTable[[#This Row],[Return_Status]]="Yes",1,0) -> 0 | AF7: =YEAR(RawSalesTable[[#This Row],[Order_Date]]) -> 2025 | AG7: =MONTH(RawSalesTable[[#This Row],[Order_Date]]) -> 5 | AH7: =TEXT(RawSalesTable[[#This Row],[Order_Date]],"mmmm") -> mai | AI7: =IF(RawSalesTable[[#This Row],[Month_Number]]<=3,"Q1",IF(RawSalesTable[[#This Row],[Month_Number]]<=6,"Q2",IF(RawSalesTable[[#This Row],[Month_Number]]<=9,"Q3","Q4"))) -> Q2 | AJ7: =DATE(YEAR(RawSalesTable[[#This Row],[Order_Date]]),MONTH(RawSalesTable[[#This Row],[Order_Date]]),1) -> 45778 | AK7: =VLOOKUP(RawSalesTable[[#This Row],[Customer_ID_clean]],CustomersTable[],4,FALSE) -> British Columbia
A8: ORD-2025-00521 | B8: 45993 | C8: C0059 | D8: P1022 | E8: Lucas Chen, Vancouver, Corporate | F8: Online Fulfillment | G8: A. Morgan | H8: Online | I8: 2 | J8: 416.28 | K8: 0 | L8: PayPal | M8: 9 | N8: No | O8: =SUBSTITUTE(PROPER(TRIM(RawSalesTable[[#This Row],[Channel_Raw]])), "Market Place", "Marketplace") -> Online | P8: =TRIM(RawSalesTable[[#This Row],[Store_Raw]]) -> Online Fulfillment | Q8: =IF(TRIM(RawSalesTable[[#This Row],[Payment_Method_Raw]])="","Non renseigné",SUBSTITUTE(TRIM(RawSalesTable[[#This Row],[Payment_Method_Raw]]),"CC","Credit Card")) -> PayPal | R8: =UPPER(PROPER(RawSalesTable[[#This Row],[Customer_ID]])) -> C0059 | S8: =TRIM(LEFT(RawSalesTable[[#This Row],[Customer_Info]],FIND(",",RawSalesTable[[#This Row],[Customer_Info]]) -1)) -> Lucas Chen | T8: =TRIM(MID(RawSalesTable[[#This Row],[Customer_Info]],FIND(",",RawSalesTable[[#This Row],[Customer_Info]])+1,FIND(",",RawSalesTable[[#This Row],[Customer_Info]],FIND(",",RawSalesTable[[#This Row],[Customer_Info]])+1)-FIND(",",RawSalesTable[[#This Row],[Customer_Info]])-1)) -> Vancouver | U8: =TRIM(RIGHT(RawSalesTable[[#This Row],[Customer_Info]], LEN(RawSalesTable[[#This Row],[Customer_Info]])-FIND(",",RawSalesTable[[#This Row],[Customer_Info]],FIND(",",RawSalesTable[[#This Row],[Customer_Info]])+1))) -> Corporate | V8: =VLOOKUP(RawSalesTable[[#This Row],[Product_ID]],ProductsTable[],2,FALSE) -> Humidifier | W8: =VLOOKUP(RawSalesTable[[#This Row],[Product_ID]],ProductsTable[],3,FALSE) -> Home | X8: =VLOOKUP(RawSalesTable[[#This Row],[Product_ID]],ProductsTable[],5,FALSE) -> 239.67 | Y8: =RawSalesTable[[#This Row],[Quantity]]*RawSalesTable[[#This Row],[Unit_Price]] -> 832.56 | Z8: =RawSalesTable[[#This Row],[Gross_Sales]]*RawSalesTable[[#This Row],[Discount_Pct]] -> 0 | AA8: =RawSalesTable[[#This Row],[Gross_Sales]]-RawSalesTable[[#This Row],[Discount_Amount]] -> 832.56 | AB8: =RawSalesTable[[#This Row],[Unit_Cost]]*RawSalesTable[[#This Row],[Quantity]] -> 479.34 | AC8: =RawSalesTable[[#This Row],[Net_Sales]]-RawSalesTable[[#This Row],[Total_Cost]] -> 353.22 | AD8: =RawSalesTable[[#This Row],[Profit]]/RawSalesTable[[#This Row],[Net_Sales]] -> 0.42425771 | AE8: =IF(RawSalesTable[[#This Row],[Return_Status]]="Yes",1,0) -> 0 | AF8: =YEAR(RawSalesTable[[#This Row],[Order_Date]]) -> 2025 | AG8: =MONTH(RawSalesTable[[#This Row],[Order_Date]]) -> 12 | AH8: =TEXT(RawSalesTable[[#This Row],[Order_Date]],"mmmm") -> décembre | AI8: =IF(RawSalesTable[[#This Row],[Month_Number]]<=3,"Q1",IF(RawSalesTable[[#This Row],[Month_Number]]<=6,"Q2",IF(RawSalesTable[[#This Row],[Month_Number]]<=9,"Q3","Q4"))) -> Q4 | AJ8: =DATE(YEAR(RawSalesTable[[#This Row],[Order_Date]]),MONTH(RawSalesTable[[#This Row],[Order_Date]]),1) -> 45992 | AK8: =VLOOKUP(RawSalesTable[[#This Row],[Customer_ID_clean]],CustomersTable[],4,FALSE) -> British Columbia
A9: ORD-2025-00536 | B9: 45669 | C9: C0051 | D9: P1037 | E9: Daniel Brown, Vancouver, Small Business | F9: Vancouver West | G9: J. Tremblay | H9: Online | I9: 2 | J9: 370.98 | K9: 0.15 | L9: Credit Card | M9: 5 | N9: No | O9: =SUBSTITUTE(PROPER(TRIM(RawSalesTable[[#This Row],[Channel_Raw]])), "Market Place", "Marketplace") -> Online | P9: =TRIM(RawSalesTable[[#This Row],[Store_Raw]]) -> Vancouver West | Q9: =IF(TRIM(RawSalesTable[[#This Row],[Payment_Method_Raw]])="","Non renseigné",SUBSTITUTE(TRIM(RawSalesTable[[#This Row],[Payment_Method_Raw]]),"CC","Credit Card")) -> Credit Card | R9: =UPPER(PROPER(RawSalesTable[[#This Row],[Customer_ID]])) -> C0051 | S9: =TRIM(LEFT(RawSalesTable[[#This Row],[Customer_Info]],FIND(",",RawSalesTable[[#This Row],[Customer_Info]]) -1)) -> Daniel Brown | T9: =TRIM(MID(RawSalesTable[[#This Row],[Customer_Info]],FIND(",",RawSalesTable[[#This Row],[Customer_Info]])+1,FIND(",",RawSalesTable[[#This Row],[Customer_Info]],FIND(",",RawSalesTable[[#This Row],[Customer_Info]])+1)-FIND(",",RawSalesTable[[#This Row],[Customer_Info]])-1)) -> Vancouver | U9: =TRIM(RIGHT(RawSalesTable[[#This Row],[Customer_Info]], LEN(RawSalesTable[[#This Row],[Customer_Info]])-FIND(",",RawSalesTable[[#This Row],[Customer_Info]],FIND(",",RawSalesTable[[#This Row],[Customer_Info]])+1))) -> Small Business | V9: =VLOOKUP(RawSalesTable[[#This Row],[Product_ID]],ProductsTable[],2,FALSE) -> Cable Set | W9: =VLOOKUP(RawSalesTable[[#This Row],[Product_ID]],ProductsTable[],3,FALSE) -> Accessories | X9: =VLOOKUP(RawSalesTable[[#This Row],[Product_ID]],ProductsTable[],5,FALSE) -> 200.16 | Y9: =RawSalesTable[[#This Row],[Quantity]]*RawSalesTable[[#This Row],[Unit_Price]] -> 741.96 | Z9: =RawSalesTable[[#This Row],[Gross_Sales]]*RawSalesTable[[#This Row],[Discount_Pct]] -> 111.294 | AA9: =RawSalesTable[[#This Row],[Gross_Sales]]-RawSalesTable[[#This Row],[Discount_Amount]] -> 630.666 | AB9: =RawSalesTable[[#This Row],[Unit_Cost]]*RawSalesTable[[#This Row],[Quantity]] -> 400.32 | AC9: =RawSalesTable[[#This Row],[Net_Sales]]-RawSalesTable[[#This Row],[Total_Cost]] -> 230.346 | AD9: =RawSalesTable[[#This Row],[Profit]]/RawSalesTable[[#This Row],[Net_Sales]] -> 0.36524246 | AE9: =IF(RawSalesTable[[#This Row],[Return_Status]]="Yes",1,0) -> 0 | AF9: =YEAR(RawSalesTable[[#This Row],[Order_Date]]) -> 2025 | AG9: =MONTH(RawSalesTable[[#This Row],[Order_Date]]) -> 1 | AH9: =TEXT(RawSalesTable[[#This Row],[Order_Date]],"mmmm") -> janvier | AI9: =IF(RawSalesTable[[#This Row],[Month_Number]]<=3,"Q1",IF(RawSalesTable[[#This Row],[Month_Number]]<=6,"Q2",IF(RawSalesTable[[#This Row],[Month_Number]]<=9,"Q3","Q4"))) -> Q1 | AJ9: =DATE(YEAR(RawSalesTable[[#This Row],[Order_Date]]),MONTH(RawSalesTable[[#This Row],[Order_Date]]),1) -> 45658 | AK9: =VLOOKUP(RawSalesTable[[#This Row],[Customer_ID_clean]],CustomersTable[],4,FALSE) -> British Columbia
A10: ORD-2025-00552 | B10: 45684 | C10: C0105 | D10: P1005 | E10: Liam Martin , Calgary , Consumer | F10: Online Fulfillment | G10: S. Patel | H10: Marketplace | I10: 1 | J10: 250.61 | K10: 0 | L10: Debit Card | M10: 2 | N10: No | O10: =SUBSTITUTE(PROPER(TRIM(RawSalesTable[[#This Row],[Channel_Raw]])), "Market Place", "Marketplace") -> Marketplace | P10: =TRIM(RawSalesTable[[#This Row],[Store_Raw]]) -> Online Fulfillment | Q10: =IF(TRIM(RawSalesTable[[#This Row],[Payment_Method_Raw]])="","Non renseigné",SUBSTITUTE(TRIM(RawSalesTable[[#This Row],[Payment_Method_Raw]]),"CC","Credit Card")) -> Debit Card | R10: =UPPER(PROPER(RawSalesTable[[#This Row],[Customer_ID]])) -> C0105 | S10: =TRIM(LEFT(RawSalesTable[[#This Row],[Customer_Info]],FIND(",",RawSalesTable[[#This Row],[Customer_Info]]) -1)) -> Liam Martin | T10: =TRIM(MID(RawSalesTable[[#This Row],[Customer_Info]],FIND(",",RawSalesTable[[#This Row],[Customer_Info]])+1,FIND(",",RawSalesTable[[#This Row],[Customer_Info]],FIND(",",RawSalesTable[[#This Row],[Customer_Info]])+1)-FIND(",",RawSalesTable[[#This Row],[Customer_Info]])-1)) -> Calgary | U10: =TRIM(RIGHT(RawSalesTable[[#This Row],[Customer_Info]], LEN(RawSalesTable[[#This Row],[Customer_Info]])-FIND(",",RawSalesTable[[#This Row],[Customer_Info]],FIND(",",RawSalesTable[[#This Row],[Customer_Info]])+1))) -> Consumer | V10: =VLOOKUP(RawSalesTable[[#This Row],[Product_ID]],ProductsTable[],2,FALSE) -> Portable SSD | W10: =VLOOKUP(RawSalesTable[[#This Row],[Product_ID]],ProductsTable[],3,FALSE) -> Electronics | X10: =VLOOKUP(RawSalesTable[[#This Row],[Product_ID]],ProductsTable[],5,FALSE) -> 131.19 | Y10: =RawSalesTable[[#This Row],[Quantity]]*RawSalesTable[[#This Row],[Unit_Price]] -> 250.61 | Z10: =RawSalesTable[[#This Row],[Gross_Sales]]*RawSalesTable[[#This Row],[Discount_Pct]] -> 0 | AA10: =RawSalesTable[[#This Row],[Gross_Sales]]-RawSalesTable[[#This Row],[Discount_Amount]] -> 250.61 | AB10: =RawSalesTable[[#This Row],[Unit_Cost]]*RawSalesTable[[#This Row],[Quantity]] -> 131.19 | AC10: =RawSalesTable[[#This Row],[Net_Sales]]-RawSalesTable[[#This Row],[Total_Cost]] -> 119.42 | AD10: =RawSalesTable[[#This Row],[Profit]]/RawSalesTable[[#This Row],[Net_Sales]] -> 0.4765173 | AE10: =IF(RawSalesTable[[#This Row],[Return_Status]]="Yes",1,0) -> 0 | AF10: =YEAR(RawSalesTable[[#This Row],[Order_Date]]) -> 2025 | AG10: =MONTH(RawSalesTable[[#This Row],[Order_Date]]) -> 1 | AH10: =TEXT(RawSalesTable[[#This Row],[Order_Date]],"mmmm") -> janvier | AI10: =IF(RawSalesTable[[#This Row],[Month_Number]]<=3,"Q1",IF(RawSalesTable[[#This Row],[Month_Number]]<=6,"Q2",IF(RawSalesTable[[#This Row],[Month_Number]]<=9,"Q3","Q4"))) -> Q1 | AJ10: =DATE(YEAR(RawSalesTable[[#This Row],[Order_Date]]),MONTH(RawSalesTable[[#This Row],[Order_Date]]),1) -> 45658 | AK10: =VLOOKUP(RawSalesTable[[#This Row],[Customer_ID_clean]],CustomersTable[],4,FALSE) -> Alberta
A11: ORD-2025-00572 | B11: 45746 | C11: C0032 | D11: P1021 | E11: Nora Bennett, Surrey, Consumer | F11: Online Fulfillment | G11: E. Roy | H11: Online | I11: 1 | J11: 298.7 | K11: 0 | L11: Debit Card | M11: 6 | N11: No | O11: =SUBSTITUTE(PROPER(TRIM(RawSalesTable[[#This Row],[Channel_Raw]])), "Market Place", "Marketplace") -> Online | P11: =TRIM(RawSalesTable[[#This Row],[Store_Raw]]) -> Online Fulfillment | Q11: =IF(TRIM(RawSalesTable[[#This Row],[Payment_Method_Raw]])="","Non renseigné",SUBSTITUTE(TRIM(RawSalesTable[[#This Row],[Payment_Method_Raw]]),"CC","Credit Card")) -> Debit Card | R11: =UPPER(PROPER(RawSalesTable[[#This Row],[Customer_ID]])) -> C0032 | S11: =TRIM(LEFT(RawSalesTable[[#This Row],[Customer_Info]],FIND(",",RawSalesTable[[#This Row],[Customer_Info]]) -1)) -> Nora Bennett | T11: =TRIM(MID(RawSalesTable[[#This Row],[Customer_Info]],FIND(",",RawSalesTable[[#This Row],[Customer_Info]])+1,FIND(",",RawSalesTable[[#This Row],[Customer_Info]],FIND(",",RawSalesTable[[#This Row],[Customer_Info]])+1)-FIND(",",RawSalesTable[[#This Row],[Customer_Info]])-1)) -> Surrey | U11: =TRIM(RIGHT(RawSalesTable[[#This Row],[Customer_Info]], LEN(RawSalesTable[[#This Row],[Customer_Info]])-FIND(",",RawSalesTable[[#This Row],[Customer_Info]],FIND(",",RawSalesTable[[#This Row],[Customer_Info]])+1))) -> Consumer | V11: =VLOOKUP(RawSalesTable[[#This Row],[Product_ID]],ProductsTable[],2,FALSE) -> Kettle | W11: =VLOOKUP(RawSalesTable[[#This Row],[Product_ID]],ProductsTable[],3,FALSE) -> Home | X11: =VLOOKUP(RawSalesTable[[#This Row],[Product_ID]],ProductsTable[],5,FALSE) -> 139.86 | Y11: =RawSalesTable[[#This Row],[Quantity]]*RawSalesTable[[#This Row],[Unit_Price]] -> 298.7 | Z11: =RawSalesTable[[#This Row],[Gross_Sales]]*RawSalesTable[[#This Row],[Discount_Pct]] -> 0 | AA11: =RawSalesTable[[#This Row],[Gross_Sales]]-RawSalesTable[[#This Row],[Discount_Amount]] -> 298.7 | AB11: =RawSalesTable[[#This Row],[Unit_Cost]]*RawSalesTable[[#This Row],[Quantity]] -> 139.86 | AC11: =RawSalesTable[[#This Row],[Net_Sales]]-RawSalesTable[[#This Row],[Total_Cost]] -> 158.84 | AD11: =RawSalesTable[[#This Row],[Profit]]/RawSalesTable[[#This Row],[Net_Sales]] -> 0.53177101 | AE11: =IF(RawSalesTable[[#This Row],[Return_Status]]="Yes",1,0) -> 0 | AF11: =YEAR(RawSalesTable[[#This Row],[Order_Date]]) -> 2025 | AG11: =MONTH(RawSalesTable[[#This Row],[Order_Date]]) -> 3 | AH11: =TEXT(RawSalesTable[[#This Row],[Order_Date]],"mmmm") -> mars | AI11: =IF(RawSalesTable[[#This Row],[Month_Number]]<=3,"Q1",IF(RawSalesTable[[#This Row],[Month_Number]]<=6,"Q2",IF(RawSalesTable[[#This Row],[Month_Number]]<=9,"Q3","Q4"))) -> Q1 | AJ11: =DATE(YEAR(RawSalesTable[[#This Row],[Order_Date]]),MONTH(RawSalesTable[[#This Row],[Order_Date]]),1) -> 45717 | AK11: =VLOOKUP(RawSalesTable[[#This Row],[Customer_ID_clean]],CustomersTable[],4,FALSE) -> British Columbia
A12: ORD-2025-00643 | B12: 46005 | C12: C0102 | D12: P1001 | E12: Adam Roy , Edmonton , Corporate | F12: Montreal Central | G12: N. Brown | H12: Online | I12: 1 | J12: 379.66 | K12: 0 | L12: PayPal | M12: 5 | N12: No | O12: =SUBSTITUTE(PROPER(TRIM(RawSalesTable[[#This Row],[Channel_Raw]])), "Market Place", "Marketplace") -> Online | P12: =TRIM(RawSalesTable[[#This Row],[Store_Raw]]) -> Montreal Central | Q12: =IF(TRIM(RawSalesTable[[#This Row],[Payment_Method_Raw]])="","Non renseigné",SUBSTITUTE(TRIM(RawSalesTable[[#This Row],[Payment_Method_Raw]]),"CC","Credit Card")) -> PayPal | R12: =UPPER(PROPER(RawSalesTable[[#This Row],[Customer_ID]])) -> C0102 | S12: =TRIM(LEFT(RawSalesTable[[#This Row],[Customer_Info]],FIND(",",RawSalesTable[[#This Row],[Customer_Info]]) -1)) -> Adam Roy | T12: =TRIM(MID(RawSalesTable[[#This Row],[Customer_Info]],FIND(",",RawSalesTable[[#This Row],[Customer_Info]])+1,FIND(",",RawSalesTable[[#This Row],[Customer_Info]],FIND(",",RawSalesTable[[#This Row],[Customer_Info]])+1)-FIND(",",RawSalesTable[[#This Row],[Customer_Info]])-1)) -> Edmonton | U12: =TRIM(RIGHT(RawSalesTable[[#This Row],[Customer_Info]], LEN(RawSalesTable[[#This Row],[Customer_Info]])-FIND(",",RawSalesTable[[#This Row],[Customer_Info]],FIND(",",RawSalesTable[[#This Row],[Customer_Info]])+1))) -> Corporate | V12: =VLOOKUP(RawSalesTable[[#This Row],[Product_ID]],ProductsTable[],2,FALSE) -> Headphones | W12: =VLOOKUP(RawSalesTable[[#This Row],[Product_ID]],ProductsTable[],3,FALSE) -> Electronics | X12: =VLOOKUP(RawSalesTable[[#This Row],[Product_ID]],ProductsTable[],5,FALSE) -> 254.6 | Y12: =RawSalesTable[[#This Row],[Quantity]]*RawSalesTable[[#This Row],[Unit_Price]] -> 379.66 | Z12: =RawSalesTable[[#This Row],[Gross_Sales]]*RawSalesTable[[#This Row],[Discount_Pct]] -> 0 | AA12: =RawSalesTable[[#This Row],[Gross_Sales]]-RawSalesTable[[#This Row],[Discount_Amount]] -> 379.66 | AB12: =RawSalesTable[[#This Row],[Unit_Cost]]*RawSalesTable[[#This Row],[Quantity]] -> 254.6 | AC12: =RawSalesTable[[#This Row],[Net_Sales]]-RawSalesTable[[#This Row],[Total_Cost]] -> 125.06 | AD12: =RawSalesTable[[#This Row],[Profit]]/RawSalesTable[[#This Row],[Net_Sales]] -> 0.32939999 | AE12: =IF(RawSalesTable[[#This Row],[Return_Status]]="Yes",1,0) -> 0 | AF12: =YEAR(RawSalesTable[[#This Row],[Order_Date]]) -> 2025 | AG12: =MONTH(RawSalesTable[[#This Row],[Order_Date]]) -> 12 | AH12: =TEXT(RawSalesTable[[#This Row],[Order_Date]],"mmmm") -> décembre | AI12: =IF(RawSalesTable[[#This Row],[Month_Number]]<=3,"Q1",IF(RawSalesTable[[#This Row],[Month_Number]]<=6,"Q2",IF(RawSalesTable[[#This Row],[Month_Number]]<=9,"Q3","Q4"))) -> Q4 | AJ12: =DATE(YEAR(RawSalesTable[[#This Row],[Order_Date]]),MONTH(RawSalesTable[[#This Row],[Order_Date]]),1) -> 45992 | AK12: =VLOOKUP(RawSalesTable[[#This Row],[Customer_ID_clean]],CustomersTable[],4,FALSE) -> Alberta
A13: ORD-2025-00711 | B13: 45750 | C13: C0006 | D13: P1003 | E13: Nora Wilson, Laval, Consumer | F13: Montreal Central | G13: M. Wilson | H13: Online | I13: 1 | J13: 153 | K13: 0 | L13: PayPal | M13: 6 | N13: No | O13: =SUBSTITUTE(PROPER(TRIM(RawSalesTable[[#This Row],[Channel_Raw]])), "Market Place", "Marketplace") -> Online | P13: =TRIM(RawSalesTable[[#This Row],[Store_Raw]]) -> Montreal Central | Q13: =IF(TRIM(RawSalesTable[[#This Row],[Payment_Method_Raw]])="","Non renseigné",SUBSTITUTE(TRIM(RawSalesTable[[#This Row],[Payment_Method_Raw]]),"CC","Credit Card")) -> PayPal | R13: =UPPER(PROPER(RawSalesTable[[#This Row],[Customer_ID]])) -> C0006 | S13: =TRIM(LEFT(RawSalesTable[[#This Row],[Customer_Info]],FIND(",",RawSalesTable[[#This Row],[Customer_Info]]) -1)) -> Nora Wilson | T13: =TRIM(MID(RawSalesTable[[#This Row],[Customer_Info]],FIND(",",RawSalesTable[[#This Row],[Customer_Info]])+1,FIND(",",RawSalesTable[[#This Row],[Customer_Info]],FIND(",",RawSalesTable[[#This Row],[Customer_Info]])+1)-FIND(",",RawSalesTable[[#This Row],[Customer_Info]])-1)) -> Laval | U13: =TRIM(RIGHT(RawSalesTable[[#This Row],[Customer_Info]], LEN(RawSalesTable[[#This Row],[Customer_Info]])-FIND(",",RawSalesTable[[#This Row],[Customer_Info]],FIND(",",RawSalesTable[[#This Row],[Customer_Info]])+1))) -> Consumer | V13: =VLOOKUP(RawSalesTable[[#This Row],[Product_ID]],ProductsTable[],2,FALSE) -> Mouse | W13: =VLOOKUP(RawSalesTable[[#This Row],[Product_ID]],ProductsTable[],3,FALSE) -> Electronics | X13: =VLOOKUP(RawSalesTable[[#This Row],[Product_ID]],ProductsTable[],5,FALSE) -> 106.4 | Y13: =RawSalesTable[[#This Row],[Quantity]]*RawSalesTable[[#This Row],[Unit_Price]] -> 153 | Z13: =RawSalesTable[[#This Row],[Gross_Sales]]*RawSalesTable[[#This Row],[Discount_Pct]] -> 0 | AA13: =RawSalesTable[[#This Row],[Gross_Sales]]-RawSalesTable[[#This Row],[Discount_Amount]] -> 153 | AB13: =RawSalesTable[[#This Row],[Unit_Cost]]*RawSalesTable[[#This Row],[Quantity]] -> 106.4 | AC13: =RawSalesTable[[#This Row],[Net_Sales]]-RawSalesTable[[#This Row],[Total_Cost]] -> 46.6 | AD13: =RawSalesTable[[#This Row],[Profit]]/RawSalesTable[[#This Row],[Net_Sales]] -> 0.30457516 | AE13: =IF(RawSalesTable[[#This Row],[Return_Status]]="Yes",1,0) -> 0 | AF13: =YEAR(RawSalesTable[[#This Row],[Order_Date]]) -> 2025 | AG13: =MONTH(RawSalesTable[[#This Row],[Order_Date]]) -> 4 | AH13: =TEXT(RawSalesTable[[#This Row],[Order_Date]],"mmmm") -> avril | AI13: =IF(RawSalesTable[[#This Row],[Month_Number]]<=3,"Q1",IF(RawSalesTable[[#This Row],[Month_Number]]<=6,"Q2",IF(RawSalesTable[[#This Row],[Month_Number]]<=9,"Q3","Q4"))) -> Q2 | AJ13: =DATE(YEAR(RawSalesTable[[#This Row],[Order_Date]]),MONTH(RawSalesTable[[#This Row],[Order_Date]]),1) -> 45748 | AK13: =VLOOKUP(RawSalesTable[[#This Row],[Customer_ID_clean]],CustomersTable[],4,FALSE) -> Quebec
A14: ORD-2025-00001 | B14: 45921 | C14: C0113 | D14: P1025 | E14: Olivia Johnson, Surrey, Consumer | F14: Online Fulfillment | G14: J. Tremblay | H14: Online | I14: 1 | J14: 321.89 | K14: 0 | L14: PayPal | M14: 1 | N14: No | O14: =SUBSTITUTE(PROPER(TRIM(RawSalesTable[[#This Row],[Channel_Raw]])), "Market Place", "Marketplace") -> Online | P14: =TRIM(RawSalesTable[[#This Row],[Store_Raw]]) -> Online Fulfillment | Q14: =IF(TRIM(RawSalesTable[[#This Row],[Payment_Method_Raw]])="","Non renseigné",SUBSTITUTE(TRIM(RawSalesTable[[#This Row],[Payment_Method_Raw]]),"CC","Credit Card")) -> PayPal | R14: =UPPER(PROPER(RawSalesTable[[#This Row],[Customer_ID]])) -> C0113 | S14: =TRIM(LEFT(RawSalesTable[[#This Row],[Customer_Info]],FIND(",",RawSalesTable[[#This Row],[Customer_Info]]) -1)) -> Olivia Johnson | T14: =TRIM(MID(RawSalesTable[[#This Row],[Customer_Info]],FIND(",",RawSalesTable[[#This Row],[Customer_Info]])+1,FIND(",",RawSalesTable[[#This Row],[Customer_Info]],FIND(",",RawSalesTable[[#This Row],[Customer_Info]])+1)-FIND(",",RawSalesTable[[#This Row],[Customer_Info]])-1)) -> Surrey | U14: =TRIM(RIGHT(RawSalesTable[[#This Row],[Customer_Info]], LEN(RawSalesTable[[#This Row],[Customer_Info]])-FIND(",",RawSalesTable[[#This Row],[Customer_Info]],FIND(",",RawSalesTable[[#This Row],[Customer_Info]])+1))) -> Consumer | V14: =VLOOKUP(RawSalesTable[[#This Row],[Product_ID]],ProductsTable[],2,FALSE) -> Yoga Mat | W14: =VLOOKUP(RawSalesTable[[#This Row],[Product_ID]],ProductsTable[],3,FALSE) -> Fitness | X14: =VLOOKUP(RawSalesTable[[#This Row],[Product_ID]],ProductsTable[],5,FALSE) -> 197.33 | Y14: =RawSalesTable[[#This Row],[Quantity]]*RawSalesTable[[#This Row],[Unit_Price]] -> 321.89 | Z14: =RawSalesTable[[#This Row],[Gross_Sales]]*RawSalesTable[[#This Row],[Discount_Pct]] -> 0 | AA14: =RawSalesTable[[#This Row],[Gross_Sales]]-RawSalesTable[[#This Row],[Discount_Amount]] -> 321.89 | AB14: =RawSalesTable[[#This Row],[Unit_Cost]]*RawSalesTable[[#This Row],[Quantity]] -> 197.33 | AC14: =RawSalesTable[[#This Row],[Net_Sales]]-RawSalesTable[[#This Row],[Total_Cost]] -> 124.56 | AD14: =RawSalesTable[[#This Row],[Profit]]/RawSalesTable[[#This Row],[Net_Sales]] -> 0.38696449 | AE14: =IF(RawSalesTable[[#This Row],[Return_Status]]="Yes",1,0) -> 0 | AF14: =YEAR(RawSalesTable[[#This Row],[Order_Date]]) -> 2025 | AG14: =MONTH(RawSalesTable[[#This Row],[Order_Date]]) -> 9 | AH14: =TEXT(RawSalesTable[[#This Row],[Order_Date]],"mmmm") -> septembre | AI14: =IF(RawSalesTable[[#This Row],[Month_Number]]<=3,"Q1",IF(RawSalesTable[[#This Row],[Month_Number]]<=6,"Q2",IF(RawSalesTable[[#This Row],[Month_Number]]<=9,"Q3","Q4"))) -> Q3 | AJ14: =DATE(YEAR(RawSalesTable[[#This Row],[Order_Date]]),MONTH(RawSalesTable[[#This Row],[Order_Date]]),1) -> 45901 | AK14: =VLOOKUP(RawSalesTable[[#This Row],[Customer_ID_clean]],CustomersTable[],4,FALSE) -> British Columbia
A15: ORD-2025-00002 | B15: 45801 | C15: C0084 | D15: P1033 | E15: Ryan Clark, Montreal, Corporate | F15: Online Fulfillment | G15: L. Chen | H15: Retail Store | I15: 4 | J15: 316.17 | K15: 0.15 | L15: Debit Card | M15: 3 | N15: No | O15: =SUBSTITUTE(PROPER(TRIM(RawSalesTable[[#This Row],[Channel_Raw]])), "Market Place", "Marketplace") -> Retail Store | P15: =TRIM(RawSalesTable[[#This Row],[Store_Raw]]) -> Online Fulfillment | Q15: =IF(TRIM(RawSalesTable[[#This Row],[Payment_Method_Raw]])="","Non renseigné",SUBSTITUTE(TRIM(RawSalesTable[[#This Row],[Payment_Method_Raw]]),"CC","Credit Card")) -> Debit Card | R15: =UPPER(PROPER(RawSalesTable[[#This Row],[Customer_ID]])) -> C0084 | S15: =TRIM(LEFT(RawSalesTable[[#This Row],[Customer_Info]],FIND(",",RawSalesTable[[#This Row],[Customer_Info]]) -1)) -> Ryan Clark | T15: =TRIM(MID(RawSalesTable[[#This Row],[Customer_Info]],FIND(",",RawSalesTable[[#This Row],[Customer_Info]])+1,FIND(",",RawSalesTable[[#This Row],[Customer_Info]],FIND(",",RawSalesTable[[#This Row],[Customer_Info]])+1)-FIND(",",RawSalesTable[[#This Row],[Customer_Info]])-1)) -> Montreal | U15: =TRIM(RIGHT(RawSalesTable[[#This Row],[Customer_Info]], LEN(RawSalesTable[[#This Row],[Customer_Info]])-FIND(",",RawSalesTable[[#This Row],[Customer_Info]],FIND(",",RawSalesTable[[#This Row],[Customer_Info]])+1))) -> Corporate | V15: =VLOOKUP(RawSalesTable[[#This Row],[Product_ID]],ProductsTable[],2,FALSE) -> Backpack | W15: =VLOOKUP(RawSalesTable[[#This Row],[Product_ID]],ProductsTable[],3,FALSE) -> Accessories | X15: =VLOOKUP(RawSalesTable[[#This Row],[Product_ID]],ProductsTable[],5,FALSE) -> 152.55 | Y15: =RawSalesTable[[#This Row],[Quantity]]*RawSalesTable[[#This Row],[Unit_Price]] -> 1264.68 | Z15: =RawSalesTable[[#This Row],[Gross_Sales]]*RawSalesTable[[#This Row],[Discount_Pct]] -> 189.702 | AA15: =RawSalesTable[[#This Row],[Gross_Sales]]-RawSalesTable[[#This Row],[Discount_Amount]] -> 1074.978 | AB15: =RawSalesTable[[#This Row],[Unit_Cost]]*RawSalesTable[[#This Row],[Quantity]] -> 610.2 | AC15: =RawSalesTable[[#This Row],[Net_Sales]]-RawSalesTable[[#This Row],[Total_Cost]] -> 464.778 | AD15: =RawSalesTable[[#This Row],[Profit]]/RawSalesTable[[#This Row],[Net_Sales]] -> 0.43236048 | AE15: =IF(RawSalesTable[[#This Row],[Return_Status]]="Yes",1,0) -> 0 | AF15: =YEAR(RawSalesTable[[#This Row],[Order_Date]]) -> 2025 | AG15: =MONTH(RawSalesTable[[#This Row],[Order_Date]]) -> 5 | AH15: =TEXT(RawSalesTable[[#This Row],[Order_Date]],"mmmm") -> mai | AI15: =IF(RawSalesTable[[#This Row],[Month_Number]]<=3,"Q1",IF(RawSalesTable[[#This Row],[Month_Number]]<=6,"Q2",IF(RawSalesTable[[#This Row],[Month_Number]]<=9,"Q3","Q4"))) -> Q2 | AJ15: =DATE(YEAR(RawSalesTable[[#This Row],[Order_Date]]),MONTH(RawSalesTable[[#This Row],[Order_Date]]),1) -> 45778 | AK15: =VLOOKUP(RawSalesTable[[#This Row],[Customer_ID_clean]],CustomersTable[],4,FALSE) -> Quebec
A16: ORD-2025-00003 | B16: 45694 | C16: C0003 | D16: P1021 | E16: Amelia Young, Ottawa, Corporate | F16: Vancouver West | G16: N. Brown | H16: Marketplace | I16: 2 | J16: 302.17 | K16: 0 | L16: Credit Card | M16: 7 | N16: No | O16: =SUBSTITUTE(PROPER(TRIM(RawSalesTable[[#This Row],[Channel_Raw]])), "Market Place", "Marketplace") -> Marketplace | P16: =TRIM(RawSalesTable[[#This Row],[Store_Raw]]) -> Vancouver West | Q16: =IF(TRIM(RawSalesTable[[#This Row],[Payment_Method_Raw]])="","Non renseigné",SUBSTITUTE(TRIM(RawSalesTable[[#This Row],[Payment_Method_Raw]]),"CC","Credit Card")) -> Credit Card | R16: =UPPER(PROPER(RawSalesTable[[#This Row],[Customer_ID]])) -> C0003 | S16: =TRIM(LEFT(RawSalesTable[[#This Row],[Customer_Info]],FIND(",",RawSalesTable[[#This Row],[Customer_Info]]) -1)) -> Amelia Young | T16: =TRIM(MID(RawSalesTable[[#This Row],[Customer_Info]],FIND(",",RawSalesTable[[#This Row],[Customer_Info]])+1,FIND(",",RawSalesTable[[#This Row],[Customer_Info]],FIND(",",RawSalesTable[[#This Row],[Customer_Info]])+1)-FIND(",",RawSalesTable[[#This Row],[Customer_Info]])-1)) -> Ottawa | U16: =TRIM(RIGHT(RawSalesTable[[#This Row],[Customer_Info]], LEN(RawSalesTable[[#This Row],[Customer_Info]])-FIND(",",RawSalesTable[[#This Row],[Customer_Info]],FIND(",",RawSalesTable[[#This Row],[Customer_Info]])+1))) -> Corporate | V16: =VLOOKUP(RawSalesTable[[#This Row],[Product_ID]],ProductsTable[],2,FALSE) -> Kettle | W16: =VLOOKUP(RawSalesTable[[#This Row],[Product_ID]],ProductsTable[],3,FALSE) -> Home | X16: =VLOOKUP(RawSalesTable[[#This Row],[Product_ID]],ProductsTable[],5,FALSE) -> 139.86 | Y16: =RawSalesTable[[#This Row],[Quantity]]*RawSalesTable[[#This Row],[Unit_Price]] -> 604.34 | Z16: =RawSalesTable[[#This Row],[Gross_Sales]]*RawSalesTable[[#This Row],[Discount_Pct]] -> 0 | AA16: =RawSalesTable[[#This Row],[Gross_Sales]]-RawSalesTable[[#This Row],[Discount_Amount]] -> 604.34 | AB16: =RawSalesTable[[#This Row],[Unit_Cost]]*RawSalesTable[[#This Row],[Quantity]] -> 279.72 | AC16: =RawSalesTable[[#This Row],[Net_Sales]]-RawSalesTable[[#This Row],[Total_Cost]] -> 324.62 | AD16: =RawSalesTable[[#This Row],[Profit]]/RawSalesTable[[#This Row],[Net_Sales]] -> 0.53714796 | AE16: =IF(RawSalesTable[[#This Row],[Return_Status]]="Yes",1,0) -> 0 | AF16: =YEAR(RawSalesTable[[#This Row],[Order_Date]]) -> 2025 | AG16: =MONTH(RawSalesTable[[#This Row],[Order_Date]]) -> 2 | AH16: =TEXT(RawSalesTable[[#This Row],[Order_Date]],"mmmm") -> février | AI16: =IF(RawSalesTable[[#This Row],[Month_Number]]<=3,"Q1",IF(RawSalesTable[[#This Row],[Month_Number]]<=6,"Q2",IF(RawSalesTable[[#This Row],[Month_Number]]<=9,"Q3","Q4"))) -> Q1 | AJ16: =DATE(YEAR(RawSalesTable[[#This Row],[Order_Date]]),MONTH(RawSalesTable[[#This Row],[Order_Date]]),1) -> 45689 | AK16: =VLOOKUP(RawSalesTable[[#This Row],[Customer_ID_clean]],CustomersTable[],4,FALSE) -> Ontario
A17: ORD-2025-00004 | B17: 45687 | C17: C0071 | D17: P1032 | E17: Ethan Lee, Surrey, Consumer | F17: Montreal Central | G17: J. Tremblay | H17: Online | I17: 1 | J17: 197.68 | K17: 0.1 | L17: PayPal | M17: 3 | N17: No | O17: =SUBSTITUTE(PROPER(TRIM(RawSalesTable[[#This Row],[Channel_Raw]])), "Market Place", "Marketplace") -> Online | P17: =TRIM(RawSalesTable[[#This Row],[Store_Raw]]) -> Montreal Central | Q17: =IF(TRIM(RawSalesTable[[#This Row],[Payment_Method_Raw]])="","Non renseigné",SUBSTITUTE(TRIM(RawSalesTable[[#This Row],[Payment_Method_Raw]]),"CC","Credit Card")) -> PayPal | R17: =UPPER(PROPER(RawSalesTable[[#This Row],[Customer_ID]])) -> C0071 | S17: =TRIM(LEFT(RawSalesTable[[#This Row],[Customer_Info]],FIND(",",RawSalesTable[[#This Row],[Customer_Info]]) -1)) -> Ethan Lee | T17: =TRIM(MID(RawSalesTable[[#This Row],[Customer_Info]],FIND(",",RawSalesTable[[#This Row],[Customer_Info]])+1,FIND(",",RawSalesTable[[#This Row],[Customer_Info]],FIND(",",RawSalesTable[[#This Row],[Customer_Info]])+1)-FIND(",",RawSalesTable[[#This Row],[Customer_Info]])-1)) -> Surrey | U17: =TRIM(RIGHT(RawSalesTable[[#This Row],[Customer_Info]], LEN(RawSalesTable[[#This Row],[Customer_Info]])-FIND(",",RawSalesTable[[#This Row],[Customer_Info]],FIND(",",RawSalesTable[[#This Row],[Customer_Info]])+1))) -> Consumer | V17: =VLOOKUP(RawSalesTable[[#This Row],[Product_ID]],ProductsTable[],2,FALSE) -> Gym Bag | W17: =VLOOKUP(RawSalesTable[[#This Row],[Product_ID]],ProductsTable[],3,FALSE) -> Fitness | X17: =VLOOKUP(RawSalesTable[[#This Row],[Product_ID]],ProductsTable[],5,FALSE) -> 132.72 | Y17: =RawSalesTable[[#This Row],[Quantity]]*RawSalesTable[[#This Row],[Unit_Price]] -> 197.68 | Z17: =RawSalesTable[[#This Row],[Gross_Sales]]*RawSalesTable[[#This Row],[Discount_Pct]] -> 19.768 | AA17: =RawSalesTable[[#This Row],[Gross_Sales]]-RawSalesTable[[#This Row],[Discount_Amount]] -> 177.912 | AB17: =RawSalesTable[[#This Row],[Unit_Cost]]*RawSalesTable[[#This Row],[Quantity]] -> 132.72 | AC17: =RawSalesTable[[#This Row],[Net_Sales]]-RawSalesTable[[#This Row],[Total_Cost]] -> 45.192 | AD17: =RawSalesTable[[#This Row],[Profit]]/RawSalesTable[[#This Row],[Net_Sales]] -> 0.25401322 | AE17: =IF(RawSalesTable[[#This Row],[Return_Status]]="Yes",1,0) -> 0 | AF17: =YEAR(RawSalesTable[[#This Row],[Order_Date]]) -> 2025 | AG17: =MONTH(RawSalesTable[[#This Row],[Order_Date]]) -> 1 | AH17: =TEXT(RawSalesTable[[#This Row],[Order_Date]],"mmmm") -> janvier | AI17: =IF(RawSalesTable[[#This Row],[Month_Number]]<=3,"Q1",IF(RawSalesTable[[#This Row],[Month_Number]]<=6,"Q2",IF(RawSalesTable[[#This Row],[Month_Number]]<=9,"Q3","Q4"))) -> Q1 | AJ17: =DATE(YEAR(RawSalesTable[[#This Row],[Order_Date]]),MONTH(RawSalesTable[[#This Row],[Order_Date]]),1) -> 45658 | AK17: =VLOOKUP(RawSalesTable[[#This Row],[Customer_ID_clean]],CustomersTable[],4,FALSE) -> British Columbia
A18: ORD-2025-00005 | B18: 45732 | C18: C0083 | D18: P1034 | E18: Amine King, Edmonton, Consumer | F18: Toronto Downtown | G18: A. Morgan | H18: Online | I18: 1 | J18: 151.79 | K18: 0 | L18: Credit Card | M18: 2 | N18: No | O18: =SUBSTITUTE(PROPER(TRIM(RawSalesTable[[#This Row],[Channel_Raw]])), "Market Place", "Marketplace") -> Online | P18: =TRIM(RawSalesTable[[#This Row],[Store_Raw]]) -> Toronto Downtown | Q18: =IF(TRIM(RawSalesTable[[#This Row],[Payment_Method_Raw]])="","Non renseigné",SUBSTITUTE(TRIM(RawSalesTable[[#This Row],[Payment_Method_Raw]]),"CC","Credit Card")) -> Credit Card | R18: =UPPER(PROPER(RawSalesTable[[#This Row],[Customer_ID]])) -> C0083 | S18: =TRIM(LEFT(RawSalesTable[[#This Row],[Customer_Info]],FIND(",",RawSalesTable[[#This Row],[Customer_Info]]) -1)) -> Amine King | T18: =TRIM(MID(RawSalesTable[[#This Row],[Customer_Info]],FIND(",",RawSalesTable[[#This Row],[Customer_Info]])+1,FIND(",",RawSalesTable[[#This Row],[Customer_Info]],FIND(",",RawSalesTable[[#This Row],[Customer_Info]])+1)-FIND(",",RawSalesTable[[#This Row],[Customer_Info]])-1)) -> Edmonton | U18: =TRIM(RIGHT(RawSalesTable[[#This Row],[Customer_Info]], LEN(RawSalesTable[[#This Row],[Customer_Info]])-FIND(",",RawSalesTable[[#This Row],[Customer_Info]],FIND(",",RawSalesTable[[#This Row],[Customer_Info]])+1))) -> Consumer | V18: =VLOOKUP(RawSalesTable[[#This Row],[Product_ID]],ProductsTable[],2,FALSE) -> Laptop Sleeve | W18: =VLOOKUP(RawSalesTable[[#This Row],[Product_ID]],ProductsTable[],3,FALSE) -> Accessories | X18: =VLOOKUP(RawSalesTable[[#This Row],[Product_ID]],ProductsTable[],5,FALSE) -> 78.95 | Y18: =RawSalesTable[[#This Row],[Quantity]]*RawSalesTable[[#This Row],[Unit_Price]] -> 151.79 | Z18: =RawSalesTable[[#This Row],[Gross_Sales]]*RawSalesTable[[#This Row],[Discount_Pct]] -> 0 | AA18: =RawSalesTable[[#This Row],[Gross_Sales]]-RawSalesTable[[#This Row],[Discount_Amount]] -> 151.79 | AB18: =RawSalesTable[[#This Row],[Unit_Cost]]*RawSalesTable[[#This Row],[Quantity]] -> 78.95 | AC18: =RawSalesTable[[#This Row],[Net_Sales]]-RawSalesTable[[#This Row],[Total_Cost]] -> 72.84 | AD18: =RawSalesTable[[#This Row],[Profit]]/RawSalesTable[[#This Row],[Net_Sales]] -> 0.47987351 | AE18: =IF(RawSalesTable[[#This Row],[Return_Status]]="Yes",1,0) -> 0 | AF18: =YEAR(RawSalesTable[[#This Row],[Order_Date]]) -> 2025 | AG18: =MONTH(RawSalesTable[[#This Row],[Order_Date]]) -> 3 | AH18: =TEXT(RawSalesTable[[#This Row],[Order_Date]],"mmmm") -> mars | AI18: =IF(RawSalesTable[[#This Row],[Month_Number]]<=3,"Q1",IF(RawSalesTable[[#This Row],[Month_Number]]<=6,"Q2",IF(RawSalesTable[[#This Row],[Month_Number]]<=9,"Q3","Q4"))) -> Q1 | AJ18: =DATE(YEAR(RawSalesTable[[#This Row],[Order_Date]]),MONTH(RawSalesTable[[#This Row],[Order_Date]]),1) -> 45717 | AK18: =VLOOKUP(RawSalesTable[[#This Row],[Customer_ID_clean]],CustomersTable[],4,FALSE) -> Alberta
... A81: ORD-2025-00068 | B81: 45968 | C81: C0080 | D81: P1005 | E81: Sarah Smith, Mississauga, Corporate | F81: Toronto Downtown | G81: L. Chen | H81: Retail Store | I81: 2 | J81: 251.66 | K81: 0.15 | L81: Credit Card | M81: 3 | N81: No | O81: =SUBSTITUTE(PROPER(TRIM(RawSalesTable[[#This Row],[Channel_Raw]])), "Market Place", "Marketplace") -> Retail Store | P81: =TRIM(RawSalesTable[[#This Row],[Store_Raw]]) -> Toronto Downtown | Q81: =IF(TRIM(RawSalesTable[[#This Row],[Payment_Method_Raw]])="","Non renseigné",SUBSTITUTE(TRIM(RawSalesTable[[#This Row],[Payment_Method_Raw]]),"CC","Credit Card")) -> Credit Card | R81: =UPPER(PROPER(RawSalesTable[[#This Row],[Customer_ID]])) -> C0080 | S81: =TRIM(LEFT(RawSalesTable[[#This Row],[Customer_Info]],FIND(",",RawSalesTable[[#This Row],[Customer_Info]]) -1)) -> Sarah Smith | T81: =TRIM(MID(RawSalesTable[[#This Row],[Customer_Info]],FIND(",",RawSalesTable[[#This Row],[Customer_Info]])+1,FIND(",",RawSalesTable[[#This Row],[Customer_Info]],FIND(",",RawSalesTable[[#This Row],[Customer_Info]])+1)-FIND(",",RawSalesTable[[#This Row],[Customer_Info]])-1)) -> Mississauga | U81: =TRIM(RIGHT(RawSalesTable[[#This Row],[Customer_Info]], LEN(RawSalesTable[[#This Row],[Customer_Info]])-FIND(",",RawSalesTable[[#This Row],[Customer_Info]],FIND(",",RawSalesTable[[#This Row],[Customer_Info]])+1))) -> Corporate | V81: =VLOOKUP(RawSalesTable[[#This Row],[Product_ID]],ProductsTable[],2,FALSE) -> Portable SSD | W81: =VLOOKUP(RawSalesTable[[#This Row],[Product_ID]],ProductsTable[],3,FALSE) -> Electronics | X81: =VLOOKUP(RawSalesTable[[#This Row],[Product_ID]],ProductsTable[],5,FALSE) -> 131.19 | Y81: =RawSalesTable[[#This Row],[Quantity]]*RawSalesTable[[#This Row],[Unit_Price]] -> 503.32 | Z81: =RawSalesTable[[#This Row],[Gross_Sales]]*RawSalesTable[[#This Row],[Discount_Pct]] -> 75.498 | AA81: =RawSalesTable[[#This Row],[Gross_Sales]]-RawSalesTable[[#This Row],[Discount_Amount]] -> 427.822 | AB81: =RawSalesTable[[#This Row],[Unit_Cost]]*RawSalesTable[[#This Row],[Quantity]] -> 262.38 | AC81: =RawSalesTable[[#This Row],[Net_Sales]]-RawSalesTable[[#This Row],[Total_Cost]] -> 165.442 | AD81: =RawSalesTable[[#This Row],[Profit]]/RawSalesTable[[#This Row],[Net_Sales]] -> 0.38670756 | AE81: =IF(RawSalesTable[[#This Row],[Return_Status]]="Yes",1,0) -> 0 | AF81: =YEAR(RawSalesTable[[#This Row],[Order_Date]]) -> 2025 | AG81: =MONTH(RawSalesTable[[#This Row],[Order_Date]]) -> 11 | AH81: =TEXT(RawSalesTable[[#This Row],[Order_Date]],"mmmm") -> novembre | AI81: =IF(RawSalesTable[[#This Row],[Month_Number]]<=3,"Q1",IF(RawSalesTable[[#This Row],[Month_Number]]<=6,"Q2",IF(RawSalesTable[[#This Row],[Month_Number]]<=9,"Q3","Q4"))) -> Q4 | AJ81: =DATE(YEAR(RawSalesTable[[#This Row],[Order_Date]]),MONTH(RawSalesTable[[#This Row],[Order_Date]]),1) -> 45962 | AK81: =VLOOKUP(RawSalesTable[[#This Row],[Customer_ID_clean]],CustomersTable[],4,FALSE) -> Ontario
A82: ORD-2025-00069 | B82: 45999 | C82: C0075 | D82: P1012 | E82: Amelia Wilson, Vancouver, Consumer | F82: Vancouver West | G82: E. Roy | H82: Retail Store | I82: 2 | J82: 84.65 | K82: 0 | M82: 1 | N82: No | O82: =SUBSTITUTE(PROPER(TRIM(RawSalesTable[[#This Row],[Channel_Raw]])), "Market Place", "Marketplace") -> Retail Store | P82: =TRIM(RawSalesTable[[#This Row],[Store_Raw]]) -> Vancouver West | Q82: =IF(TRIM(RawSalesTable[[#This Row],[Payment_Method_Raw]])="","Non renseigné",SUBSTITUTE(TRIM(RawSalesTable[[#This Row],[Payment_Method_Raw]]),"CC","Credit Card")) -> Non renseigné | R82: =UPPER(PROPER(RawSalesTable[[#This Row],[Customer_ID]])) -> C0075 | S82: =TRIM(LEFT(RawSalesTable[[#This Row],[Customer_Info]],FIND(",",RawSalesTable[[#This Row],[Customer_Info]]) -1)) -> Amelia Wilson | T82: =TRIM(MID(RawSalesTable[[#This Row],[Customer_Info]],FIND(",",RawSalesTable[[#This Row],[Customer_Info]])+1,FIND(",",RawSalesTable[[#This Row],[Customer_Info]],FIND(",",RawSalesTable[[#This Row],[Customer_Info]])+1)-FIND(",",RawSalesTable[[#This Row],[Customer_Info]])-1)) -> Vancouver | U82: =TRIM(RIGHT(RawSalesTable[[#This Row],[Customer_Info]], LEN(RawSalesTable[[#This Row],[Customer_Info]])-FIND(",",RawSalesTable[[#This Row],[Customer_Info]],FIND(",",RawSalesTable[[#This Row],[Customer_Info]])+1))) -> Consumer | V82: =VLOOKUP(RawSalesTable[[#This Row],[Product_ID]],ProductsTable[],2,FALSE) -> Standing Desk | W82: =VLOOKUP(RawSalesTable[[#This Row],[Product_ID]],ProductsTable[],3,FALSE) -> Office | X82: =VLOOKUP(RawSalesTable[[#This Row],[Product_ID]],ProductsTable[],5,FALSE) -> 45.17 | Y82: =RawSalesTable[[#This Row],[Quantity]]*RawSalesTable[[#This Row],[Unit_Price]] -> 169.3 | Z82: =RawSalesTable[[#This Row],[Gross_Sales]]*RawSalesTable[[#This Row],[Discount_Pct]] -> 0 | AA82: =RawSalesTable[[#This Row],[Gross_Sales]]-RawSalesTable[[#This Row],[Discount_Amount]] -> 169.3 | AB82: =RawSalesTable[[#This Row],[Unit_Cost]]*RawSalesTable[[#This Row],[Quantity]] -> 90.34 | AC82: =RawSalesTable[[#This Row],[Net_Sales]]-RawSalesTable[[#This Row],[Total_Cost]] -> 78.96 | AD82: =RawSalesTable[[#This Row],[Profit]]/RawSalesTable[[#This Row],[Net_Sales]] -> 0.46639102 | AE82: =IF(RawSalesTable[[#This Row],[Return_Status]]="Yes",1,0) -> 0 | AF82: =YEAR(RawSalesTable[[#This Row],[Order_Date]]) -> 2025 | AG82: =MONTH(RawSalesTable[[#This Row],[Order_Date]]) -> 12 | AH82: =TEXT(RawSalesTable[[#This Row],[Order_Date]],"mmmm") -> décembre | AI82: =IF(RawSalesTable[[#This Row],[Month_Number]]<=3,"Q1",IF(RawSalesTable[[#This Row],[Month_Number]]<=6,"Q2",IF(RawSalesTable[[#This Row],[Month_Number]]<=9,"Q3","Q4"))) -> Q4 | AJ82: =DATE(YEAR(RawSalesTable[[#This Row],[Order_Date]]),MONTH(RawSalesTable[[#This Row],[Order_Date]]),1) -> 45992 | AK82: =VLOOKUP(RawSalesTable[[#This Row],[Customer_ID_clean]],CustomersTable[],4,FALSE) -> British Columbia
